C:/Users/Lilti/Documents/LEARNING/PROGRAMMING/z.2.Source_code/Python/Python_ATOM/Django_REST/recipe-app-api-advanced


f48c0b2d017d 5e96ae017cd6 4a2edbc4d00a 0c398ce68ef0 8a1bdb041889 6908c1b350b5 4a69bd4d2240 a707802a7f53


File "/usr/local/lib/python3.7/site-packages/psycopg2/__init__.py", line 130, in connect
      conn = _connect(dsn, connection_factory=connection_factory, **kwasync)
  django.db.utils.OperationalError: could not connect to server: Connection refused
         Is the server running on host "db" (172.23.0.2) and accepting
         TCP/IP connections on port 5432?
